Workbook

Sheet input
A1: 항목 | B1: 입력키 | C1: 값 | D1: 단위
A2: 기준적용일 | B2: Standard application date
A3: 정격하중 | B3: payload | D3: kg
A4: 최대정원 | B4: personnel | D4: 인승
A5: 정격속도 | B5: rated_speed | D5: m/s
A6: 전동기용량 | B6: motor_power | D6: kW
A7: 정격전압 | B7: rated_voltage | D7: V
A8: 정격전류 | B8: rated_current | D8: A
A9: 카치수(폭) | B9: car_width | D9: m
A10: 카치수(안길이) | B10: car_depth | D10: m
A11: 카출입구치수(폭) | B11: car_door_width | D11: m
A12: 카출입구치수(높이) | B12: car_door_height | D12: m
A13: 매다는장치의 두께 | B13: suspension_thickness | D13: mm
A14: 매다는장치의 가닥수 | B14: suspension_strand_count | D14: 가닥
... A17: 균형추 주행안내레일 | B17: cwt_guide_rail | D17: (K(T))
A18: CAR 로프 단말처리 | B18: car_rope_terminal | C18: 체결, 압착링, 스웨이지, 기타 | D18: 선택
A19: CWT 로프 단말처리 | B19: cwt_rope_terminal | C19: 체결, 압착링, 스웨이지, 기타 | D19: 선택
A20: 공급전원 전압(건물측) | B20: supply_voltage_building | D20: V
A21: 공급전원 주파수(건물측) | B21: supply_freq_building | D21: Hz
A22: 구동기 공간 | B22: machine_space | C22: MR, MRL | D22: 선택
A23: 구동기 방식 | B23: drive_type | C23: 권상구동식, 권동식, 유압식 | D23: 선택
A24: 균형추 무게 | B24: cwt_weight | D24: kg
A25: 기계실 위치 | B25: machine_room_location | C25: 기계실 내부, 승강로 상부, 승강로 하부, 기타 | D25: 선택
A26: 기어형식 | B26: gear_type | C26: GL, WG | D26: 선택
A27: 도킹운전 | B27: docking_operation | C27: 무, 유 | D27: 선택
A28: 문개폐 방식 | B28: door_operator_type | C28: CO, SO, VO | D28: 선택
A29: 문의 동작 | B29: door_motion | C29: 동력문, 반자동 동력, 수동 | D29: 선택
A30: 보상로프(체인) | B30: compensation_rope | C30: 무, 유 | D30: 선택
A31: 보상수단 종류 | B31: compensation_type | C31: 보상체인, 보상로프 | D31: 선택
A32: 보조전원 공급장치(비상용) | B32: ups_emergency | C32: 자가, 해당없음 | D32: 선택
A33: 비상구출구 | B33: emergency_exit | C33: 천정, 카 옆 | D33: 선택
A34: 승강로 내의 기계류 작업구역 | B34: machinery_work_zone | C34: 승강로 상부, 승강로 하부, 해당없음 | D34: 선택
A35: 승강로구획 | B35: hoistway_enclosure | C35: 밀폐식, 반밀폐식 | D35: 선택
A36: 승강장문 11m 초과 | B36: landing_door_over11m | C36: 무, 유 | D36: 선택
A37: 오버밸런스 | B37: overbalance | D37: %
A38: 완충기 | B38: buffer_type | C38: 유압, 우레탄, 스프링 | D38: 선택
A39: 완충기 행정(균형추 측) | B39: buffer_stroke_cwt | D39: mm
A40: 완충기 행정(카 측) | B40: buffer_stroke_car | D40: mm
A41: 카 완충기 거리 | B41: car_buffer_distance_meas | D41: mm
A42: 균형추 완충기거리 | B42: cwt_buffer_distance | D42: mm
...

Sheet rules
A1: 항목 | B1: 입력키 | C1: 입력값 | D1: 최소값 | E1: 최대값 | F1: 단위 | G1: 적합여부
A2: 비상운전 및 작동시험을 위한 장치 조도 | B2: em_operation_lux | D2: 200 | F2: lx
A3: 기계실 작업공간의 바닥 면 조도 | B3: machine_room_lux | D3: 200 | F3: lx
A4: 기계실 작업공간 간 이동 공간의 바닥면 조도 | B4: machine_access_way_lux | D4: 50 | F4: lx
A5: 권상식 카 측 레일의 연장 길이 | B5: traction_car_rail_extension | D5: 0.1 | F5: m
A6: 권상식 승강로 천장의 가장 낮은 부분과 카 지붕의 가장 높은 부분 수직거리 | B6: traction_overhead_clearance | D6: 0.5 | F6: m
A7: 권상식 승강로 천장의 가장 낮은 부분과 수평거리 0.4m 이내의 부품 수직거리 | B7: traction_overhead_clearance_04m | D7: 0.1 | F7: m
A8: 피트 바닥과 카의 가장 낮은 부분 사이의 유효 수직거리 | B8: pit_clearance_car_lowest | D8: 0.5 | F8: m
A9: 피트 바닥과 인접한 벽에서 수평거리 0.15m 이내 부품과의 수직거리 | B9: pit_clearance_wall_015m | D9: 0.1 | F9: m
A10: 피트 바닥과 주행안내 레일에서 최대 수평거리 이내 부품 수직거리 | B10: pit_clearance_rail | D10: 0.1 | F10: m
A11: 피트에서 고정된 가장 높은 부분과 카의 가장 낮은 부분 유효 수직거리 | B11: pit_clearance_fixed_highest | D11: 0.3 | F11: m
A12: 균형추 또는 평형추의 레일 연장길이 | B12: cwt_rail_extension | D12: 0.1 | F12: m
A13: 승강장문 어린이 손끼임 방지수단 틈새 | B13: landing_door_finger_gap | E13: 5 | F13: mm
A14: 카 지붕/피트 바닥에서 1m 떨어진 곳의 조도 | B14: car_roof_pit_lux_1m | D14: 50 | F14: lx
A15: 최대정원 | B15: personnel | E15: =input!C3/75 -> 0 | F15: 인승
A16: 카 유효면적 | B16: car_usable_area | D16: =IF( BS!D1>20, 3.13 + 0.115*(BS!D1-20), XLOOKUP(BS!D1, BS!$D$2:$D$21, BS!$E$2:$E$21) ) -> #NAME? | E16: =IF( BS!A1>2500, 5 + 0.0016*(BS!A1-2500), INDEX(BS!$B$2:$B$28, MATCH(BS!A1, BS!$A$2:$A$28, 1)) + (BS!A1 - INDEX(BS!$A$2:$A$28, MATCH(BS!A1, BS!$A$2:$A$28, 1))) * (INDEX(BS!$B$2:$B$28, MATCH(BS!A1, BS!$A$2:$A$28, 1)+1) - INDEX(BS!$B$2:$B$28, MATCH(BS!A1, BS!$A$2:$A$28, 1))) / (INDEX(BS!$A$2:$A$28, MATCH(BS!A1, BS!$A$2:$A$28, 1)+1) - INDEX(BS!$A$2:$A$28, MATCH(BS!A1, BS!$A$2:$A$28, 1))) ) -> #N/A | F16: ㎡
A17: 카 조작반/카 벽에서 100mm 이상 떨어진 카 바닥 위 1m 조도 | B17: car_panel_lux | D17: 100 | F17: lx
A18: 비상통화장치, 카 바닥 위 1m 지점 카 중심부 비상등 조도 | B18: em_light_floor_lux | D18: 5 | F18: lx
A19: 비상통화장치, 카 지붕 바닥 위 1m 지점 카 지붕 중심부 비상등 조도 | B19: em_light_roof_lux | D19: 5 | F19: lx
A20: 카문 어린이 손끼임 방지수단 틈새 | B20: car_door_finger_gap | E20: 5 | F20: mm
A21: 승강장 바닥 조도 | B21: landing_floor_lux | D21: 50 | F21: lx
A22: 브레이크 감속도(정격하중의 125% 하강방향) | B22: suspension_thickness_meas | E22: 1 | F22: g
A23: 최대 부하에서 전류 | B23: full_load_current | E23: =input!C8 -> 0 | F23: A
A24: 무부하 상승 속도 | B24: no_load_up_speed | D24: =input!C5*0.92 -> 0 | E24: =input!C5*1.05 -> 0 | F24: m/s
A25: 무부하 상승 전류 | B25: no_load_up_current | E25: =input!C8 -> 0 | F25: A
A26: 무부하 하강 속도 | B26: no_load_down_speed | D26: =input!C5*0.92 -> 0 | E26: =input!C5*1.05 -> 0 | F26: m/s
A27: 무부하 하강 전류 | B27: no_load_down_current | E27: =input!C8 -> 0 | F27: A
A28: 오버밸런스율 상승 속도 | B28: overbalance_up_speed | D28: =input!C5*0.92 -> 0 | E28: =input!C5*1.05 -> 0 | F28: m/s
A29: 오버밸런스율 상승 전류 | B29: overbalance_up_current | E29: =input!C8 -> 0 | F29: A
A30: 오버밸런스율 하강 속도 | B30: overbalance_down_speed | D30: =input!C5*0.92 -> 0 | E30: =input!C5*1.05 -> 0 | F30: m/s
A31: 오버밸런스율 하강 전류 | B31: overbalance_down_current | E31: =input!C8 -> 0 | F31: A
A32: 정격하중 상승 속도 | B32: rated_load_up_speed | D32: =input!C5*0.92 -> 0 | E32: =input!C5*1.05 -> 0 | F32: m/s
A33: 정격하중 상승 전류 | B33: rated_load_up_current | E33: =input!C8 -> 0 | F33: A
A34: 정격하중 하강 속도 | B34: rated_load_down_speed | D34: =input!C5*0.92 -> 0 | E34: =input!C5*1.05 -> 0 | F34: m/s
A35: 정격하중 하강 전류 | B35: rated_load_down_current | E35: =input!C8 -> 0 | F35: A
A36: 오버밸런스율 착상 속도 | B36: overbalance_setting_speed | E36: 0.8 | F36: m/s
A37: 오버밸런스율 재착상 속도 | B37: overbalance_resettling_speed | E37: 0.3 | F37: m/s
A38: 오버밸런스율 점검운전 속도 | B38: overbalance_inspection_speed | E38: 0.63 | F38: m/s
A39: 오버밸런스율 비상운전 속도 | B39: overbalance_em_speed | E39: 0.3 | F39: m/s
A40: 전동기 절연저항 | B40: motor_insulation_resistance | D40: 1 | F40: ㏁
...

Sheet rules_stand
A1: 항목 | B1: 관련 기준 | C1: 기준적용일 | D1: 기준전환일 | E1: 기준내용
A2: 승강기 번호 | B2: 5.3 | C2: 45033 | E2: ① 승강기번호 표지의 발급 a. 훼손 등의 사유로 재발급은 공단으로 신청 b. 제작 및 발송에 따른 기간 소요 적용 ② 재발급 신청 후 표지 미부착의 검사판정 a. 안전검사 시 임시번호판*의 부착 허용 * 재발급 신청 시 출력 가능 b. 승강기번호 표지의 재발급 완료 시 관리주체 (또는 신청인)는 승강기번호 표지를 부착할 것
A3: 피트 내 배수 설비 | B3: 6.1.2 | C3: 44377 | E3: ① 설치검사 시 피트 내 물을 배수할 목적의 배 수설비 설치 불가(소방구조용, 피난용 제외) ② 소방구조용 및 피난용 엘리베이터 이외 용도의 엘리베이터에도 피트 침수를 대비한 배수 관련 설비를 설치할 수 있음. 다만, 누수가 있는 경우 누수가 없도록 조치하여야 하고, 누수되는 물을 배수설비로 배수하는 것은 적합하지 않음
A4: 피트 내 배수 설비 | B4: 6.1.2 | C4: 45323 | E4: ① 레일, 완충기 등의 하중이 부과되는 위치에 집수정 설치 불가 ② 다만, 건설사와 승강기 제조사가 ①의 경우 관련법령/고시에서 명시하는 하중을 지지할 수 있음을 기술서류를 통해 증명하는 경우 허용
A5: LCD 모니터 | B5: 6.1.2 | C5: 44488 | E5: ① 신규 승강기에 설치 시 a. 제조사: 해당 기기 및 설비가 새로운 승강기 안전기준에 적합한지 증명 b. 유지관리: 승강기 제조사는 승강로 내 유선 또는 무선전송기기에 대한 사용설명서(적용범위 등) 및 품질보증서를 관리주체에 제공하고, 관리주체는 승강기 제조사 또는 유지관리업체를 통한 고장·수리 및 유지관리가 될 수 있도록 조치 ※고장또는수리시안전한작업방법(과도한 개구부발생시키지않는등)에 대해 사용 설명서에포함 ② 기존 승강기에 설치 시 a. 관리주체: 해당 기기 설치 시 안전성 등을 승강기 제조사로부터 확인을 받고 설치(해당 기기 및 설비가 새로운 승강기 안전기준에 적합한지 증명 필요) b. 유지관리: 해당 기기의 제조사는 승강로 내 유선 또는 무선전송기기에 대한 사용설명서(적용범위 등) 및 품질보증서를 관리주체에 제공하고, 관리주체는 승강기 제조사 또는 유지관리업체를 통한 고장·수리 및 유지관리가 될 수 있도록 조치 ※고장또는수리시안전한작업방법(과도한개구부발생시키지않는등)에 대해 사용설명서에포함 ★ 승강기의 JAMB 또는 삼방틀에 설치되어 승강로에 전선 등 관련설비가 있는 경우 적용되는 사항으로, 별도 건축물의 승강로 외벽에 설치되는 모니터와 전광판은 해당 없음
A6: 승강로 조명 | B6: 6.1.4.1, 6.1.5.1 | C6: 44663 | E6: ① 6.1.4.1 기준의 정의 가) 카 지붕에서 수직투영면의 1m 상부[50lx] 가),나) 사람이 서 있을 수 있는 공간, 작업구역 및 작업구역 간 이동 공간에 대한 안전 조명[50lx] 다) 승강로 전 구간에서 돌출물 또는 이동하는부품이 접근하는 등에 대한 위험의 시각적인 인지를 위한 안전조명[20lx] ★ 승강로 조명장치의 일부로 카 지붕에 조명을 추가로 고정: 카 조명과 별도로 14.1.1.1 및 14.7.1에 따라 연결된 승강로 조명의 일부 ★ 손전등과 같은 임시조명: 승강로 조명 외 전문 작업을 위해 작업면을 비추는 별도의 국부조명 ② 승강로 조명 스위치 a. 피트 출입문 및 주개폐기 근처에 각각 켜고 끌 수 있는 스위치 b. 카 상부 추가 조명장치가 설치되는 경우 카 상부에 스위치를 추가로 설치할 수 있으나 다른 승강로 조명 스위치와 동일하게 승강로 전체 조명을 켜고 끌 수 있어야 함(승강로 조명과 별도로 작동되는 조명은 승강로 조명 인정 불가) ★ 14.8.2의 추가적인 램프 정의 승강로 조명과 별도로 카 조명과 연결되어 고장 등으로 인한 승강로 조명 부재 시 대체할 수 있는 조명(승강로 조명 인정 불가) ★ 카 상부 작업등의 적용 여부 승강로 조명 라인이 결선된 카 상부 승강로 조명은 카 상부 조도 측정 시 포함되나, 카 조명 라인에 결선된 카 상부 작업등은 카 상부 조도 측정 시 적용 불가 ③ 승강로 조명 검사방법 a. 가)에 대한 검사방법 카 지붕에서 수직투영면의 1m 위치에서 승강로 및 카 위에 고정 설치된 조명의 광원을 향하여 측정(카 조명에 연결된 카 상부 작업등 제외) b. 나)에 대한 검사방법 피트 내 사람이 서 있을 수 있는 공간, 작업공간 및 작업공간간 이동통로 바닥에서 수직 위로 1m 위치에서 승강로에 고정 설치된 조명의 광원을 향하여 측정 c. 다)에 대한 검사방법 카 지붕 및 피트바닥의 1m 이상, 카 지붕에서 수직투영면 이외 공간에서 승강로에 고정 설치된 조명의 광원을 향하여 측정
A7: 피트 내 정지스위치 및 조명 점멸 수단 위치 | B7: 6.1.5.1 | C7: 45323 | E7: ① 피트 정지스위치 위치 a. 피트 깊이가 1.6m 이하인 경우 - 최하층 승강장 바닥에서 수직 위로 최소 0.4m 및 피트 바닥에서 수직 위로 최대 2m - 승강장문 안쪽 문틀에서 수평으로 최대 0.75m b. 피트 깊이가 1.6m 초과인 경우 - 상부: 최하층 승강장 바닥에서 수직 위로 최소 1m 및 승강장문 안쪽 문틀에서 수평으로 최대 0.75m - 하부: 피트 바닥에서 수직 위로 최대 1.2m 및 피난 공간에서 조작이 가능한 위치 c. 승강장문을 제외한 피트 출입문이 있는 경우 출입문 안쪽 문틀에서 수평으로 최대 0.75m 및 피트바닥에서 수직 위로 1.2m 위치에 있어야 함 ② 피트 내 조명 점멸 수단 위치 a. 피트 출입문 안쪽 문틀에서 수평으로 최대 0.75m 및 피트 출입층 바닥 위로 1m 위치에 설치
A8: 기계대 지지방법 | B8: 6.1.8.1 | C8: 45658 | E8: [설치검사(신규,교체) 시 기계대가 옹벽에 묻힌 경우] 1. 신규 설치검사 ① 기계대가 옹벽에 100 mm 이상 묻혔을 경우 : 별도의 확인서 불필요 ② 기계대가 옹벽에 100mm 미만 또는 묻히지 않았을 경우 : 구조기술사 확인서 필요 (동일한 구조의 경우 하나의 확인서 제출 가능) 2. 교체 설치검사(기계대의 이동·변경 등이 없는 경우) ① 묻힘량 확인이 불가한 경우 a. 정격하중이 종전보다 이하인 경우: 별도의 확인서 불필요 b. 정격하중이 증가되었으나 카 자중이 낮아 하중이(카 자중+정격하중) 종전보다 이하인 경우: 공인계량증명소의 계량증명서(자재 상차 사진, 하차 사진 포함) 또는 카 체대 등에 대한 부재별 무게를 계산한 중량 계산서 제출 시 인정 c. 종전보다 하중(카 자중+정격하중)이 초과한 경우: 구조기술사 확인서 필요 ② 묻힘량 확인이 가능한 경우 a. 기계대가 옹벽에 100 mm 이상 묻혔을 경우: 별도의 확인서 불필요 b. 기계대가 옹벽에 100mm 미만 또는 묻히지 않았을 경우 ㄱ. 정격하중이 종전보다 이하인 경우: 별도의 확인서 불필요 ㄴ. 정격하중이 증가되었으나 카 자중이 낮아 하중이(카 자중+정격하중) 종전보다 이하인 경우: 공인계량증명소의 계량증명서(자재 상차 사진, 하차 사진 포함) 또는 카 체대 등에 대한 부재별 무게를 계산한 중량 계산서 제출 시 인정 ㄷ. 종전보다 하중(카 자중+정격하중)이 초과한 경우: 구조기술사 확인서 필요 [검사방법] 기계대의 옹벽 묻힘량 확인(설계도면 및 현장확인 등) [표준화 적용 방안] '25. 1. 1. 이후 설치검사(신규, 교체)부터 적용
A9: 기계대 지지방법 | B9: 6.1.8.1 | C9: 45658 | E9: [설치검사(신규,교체) 시 기계대가 헌치보에 얹힌 경우] 1. 신규 설치검사 ① 지지보빔(스페이스빔)의 안전계수가 4 이상이고, 지지보빔의 벽면쪽 끝단과 벽면(구조벽 수직 연장선면)의 이격거리가 30mm 이내일 경우 : 별도의 확인서 불필요 ② 지지보빔(스페이스빔)의 벽면쪽 끝단과 벽면(구조벽 수직 연장선면)의 이격거리가 30mm 초과할 경우: 구조기술사 확인서 필요 (동일한 구조의 경우 하나의 확인서 제출 가능) 2. 교체 설치검사(기계대의 이동·변경 등이 없는 경우) ① 얹힘량 확인이 불가한 경우 a. 종전과 동일한 하중(카 자중+정격하중)이거나 이하인 경우: 별도의 확인서 불필요 b. 정격하중이 증가되었으나 카 자중이 낮아 하중이(카 자중+정격하중) 종전보다 이하인 경우: 공인계량증명소의 계량증명서(자재 상차 사진, 하차 사진 포함) 또는 카 체대 등에 대한 부재별 무게를 계산한 중량 계산서 제출 시 인정 c. 종전보다 하중(카 자중+정격하중)이 초과한경우: 구조기술사 확인서 필요 ② 얹힘량 확인이 가능한 경우 a. 지지보빔(스페이스빔)의 안전계수가 4 이상이고, 지지보빔의 벽면쪽 끝단과 벽면(구조벽 수직 연장선면)의 이격거리가 30mm 이내일 경우: 별도의 확인서 불필요 b. 지지보빔(스페이스빔)의 벽면쪽 끝단과 벽면(구조벽 수직 연장선면)의 이격거리가 30mm 초과할 경우 ㄱ. 종전과 동일한 하중(카 자중+정격하중)이거나 이하인 경우: 별도의 확인서 불필요 ㄴ. 정격하중이 증가되었으나 카 자중이 낮아 하중이(카 자중+정격하중) 종전보다 이하인 경우: 공인계량증명소의 계량증명서(자재 상차 사진, 하차 사진 포함) 또는 카 체대 등에 대한 부재별 무게를 계산한 중량 계산서 제출 시 인정 ㄷ. 종전보다 하중(카 자중+정격하중)이 초과한 경우: 구조기술사 확인서 필요 [검사방법] 기계대의 지지보빔 얹힘량 확인(설계도면 및 현장확인 등) [표준화 적용 방안] - '25. 1. 1. 이후 설치검사(신규, 교체)부터 적용
A10: 승강로 벽 | B10: 6.1.8.2 | C10: 42370 | E10: [기존 건축물에 승강로 구획하는 경우] ① 별도의 건축허가(증·개축 등)의 행정절차가 필요없는 경우 공사계약일에 따라 검사기준 적용 ② 구조강도계산서 등의 증빙 서류 제출
A11: 승강로 벽 접합유리 | B11: 6.1.8.3 | C11: 46023 | E11: 승강로 벽을 유리로 구획하는 경우 승강로 벽의 외부를 감싸는 벽면(건물 외벽 포함)의 재질은 KS L 2004에 적합한 접합유리만 사용하여야 함 ① 복층유리를 사용하는 경우 승강로 외부는 KS L 2004에 적합한 접합유리 사용 ② 사람이 접근할 수 있는 곳에 있는 평면 또는 성형된 유리판이 승강로 벽으로만 구획되는 경우에는 KS L 2004에 적합한 접합유리로 만들어져야 함 ★ 승강로 벽의 유리판 및 고정설비 강도 확인 ❶ KS 인증서- 현장에 설치된 유리에 KS L 2004 표기 ❷ 공인기관의 KS 시험성적서 및 납품확인서 (해외에서 납품 시 번역 자료 제출)- 시험성적서와 납품확인서 모델명 동일하여야 함
A12: 피트 바닥 평탄화 | B12: 6.1.9.3 | C12: 43238 | E12: 배수시설 주위에 과도한 구멍 등으로 피트바닥이 평탄하지 못한 경우 작업자의 점검이 원활하도록 커버 등으로 보완 처리
A13: 비상문 접근 통로 조명 | B13: 6.2.2 | C13: 45119 | E13: 안전기준에서 비상문으로의 접근통로의 조명은 별도 규정하지 않음
A14: 작업구역의 접근 통로 | B14: 6.2.3 | C14: 45119 | E14: [개인적인 공간 경유] ① MRL의 제어패널이 위치한 곳이 개인적인 공간을 경유하도록 설계되어 출입문의 카드키나 비밀번호를 유지관리업체에 제공하여 상시로 출입이 가능하더라도 안전기준에 부적합함 ② 개인적인 공간의 경유는 주택용 엘리베이터에 한정하여 허용
... A26: 출입문 디지털 도어록 | B26: 6.3.3 | C26: 43892 | E26: 배터리 방전 시 잠금이 유지되고 엘리베이터 안전기준에 적합한 구조인 경우 적용 가능
A27: 표시 | B27: 6.4 | C27: 42763 | E27: [기계실 출입문 경고문구] ① 경고문에 “기계실” 문구 명기되어 있고 ② “경고에 대한 문구”가 있으면 적합
A28: 에어컨 물 배수 | B28: 6.5.1.5 | C28: 45589 | E28: ① 자가증발식 에어컨: 적합 ② 에어컨 누수 또는 운행 중 상시 배수: 부적합 ③ 승강로 내부(승강로 공간, 피트 바닥 등)로 물이 흐르거나 비산하지 않는 방법 ④ 최하층에 도착 시에만 드레인 호스에서 물을 피트내 별도의 물 보관 용기로 배수
A29: 피트 내부 벽 돌출부 또는 수평 빔 | B29: 6.5.2.2.2 | C29: 45139 | E29: 피트 바닥에서 최하층 승강장에 착상한 승강기 천장까지의 승강로 공간에 승강로 내부 벽 수평 돌출부 또는 수평빔 등의 경우 카 상부 보호난간의 설치와 별도로 보호조치 하여야 함
A30: 가상 층에서의 문 열림 | B30: 6.5.3.1 | C30: 44747 | E30: 가상층이 존재하는 경우 가상층에서 정지하고 카문이 열리지 않도록 철저한 유지관리 안내(제어기판 교체 시 또는 과거 교체 이력이 있는 경우 데이터 입력값 확인)
A31: 카 출입문과 마주하는 승강로 벽의 재사용 | B31: 6.5.3.1 | C31: 44747 | E31: 기존 보호면의 재 사용·철거 등에 대해 규정하지 않음
A32: 승강장 문의 문턱 아랫부분 | B32: 6.5.3.2 | C32: 42503 | E32: [승강장문 문턱과 수직면 사이 수평거리] ① 승강장문 문턱의 돌출부분과 수직면 사이의 수평거리 〈 5mm : 적합 ② 2mm〈승강장문 문턱의 돌출부분과 수직면 사이의 수평 거리 〈 5mm : 승강장문 문턱 돌출부분의 아랫부분을 수평면에 75° 이상 모따기
A33: 승강로 하부에 위치한 공간의 보호 | B33: 6.5.4 | C33: 43559 | E33: [교체공사 시 승강로 하부 공간 보호] ① 종전 건축물로 승강기 하부에 접근이 가능한 통로가 있는 경우 a. 피트 기초 5,000N/m2의 설계 자료: 건축허가서로 갈음 b. 균형추 또는 평형추에 추락방지안전장치 설치 ② 종전 건축물로 승강기 하부에 접근이 가능한 통로가 있고, 직하부 또는 지면까지 벽이 설치되어 있는 경우 a. 피트 기초 5,000N/m2의 설계 자료: 건축허가서로 갈음 b. 균형추 또는 평형추의 추락방지안전장치 제외 가능
A34: 칸막이 | B34: 6.5.5 | C34: 45119 | E34: [균형추 주행안내레일과 승강로 벽 사이] ① 균형추 투영면적 후면과 승강로 벽까지의 거리가 0.3 m 이상인 경우 칸막이 설치 ② 후면 칸막이 설치, 접근방지수단(판) 설치, 접근 방지수단(봉) 설치
A35: 칸막이 | B35: 6.5.5 | C35: 42503 | E35: [카간 칸막이 설치] ① 수시검사 시 a. 카 교체(카 체대+카 판넬) 시 카간 칸막이 설치 대상 b. 건축구조상 설치가 불가능하고 서류로 증명 가능하다면 제외 가능 ② 설치검사 시 a. 카 지붕 모서리(카 위 작업자 공간 등)에서 인접하는 카의 움직이는 부품까지의 거리가 0.5 m 미만인 경우 전 구간 칸막이 설치 ★ 카, 균형추 또는 평형추와 연결된 부품도 엘리베이터의 움직이는 부품에 포함 (도르래 및 커버)하되, 승강로 전 구간에 걸쳐 연속적으로 이어져 있는 과속조절기 로프와 그 연결장치는 움직이는 부품에서 제외
A36: 칸막이 | B36: 6.5.5 | C36: 42503 | E36: [균형추 칸막이 설치] ① 균형추 칸막이 하부 높이는 피트 바닥에서 0.3 m 이하 ② 균형체인·로프간섭 등 부득이한 경우 완충기의 최저 이동 높이 이하
A37: 칸막이 | B37: 6.5.5 | C37: 43892 | E37: [균형추 칸막이 최저점 높이] ① 칸막이는 완전히 압축된 완충기 위에 있는 균형추 또는 가장 낮은곳에 있는 평형추의 끝단에서부터 위로 연장되어야 하며 그 연장 높이는 피트 바닥으로부터 2m 이상 ② 칸막이의 가장 낮은 부분은 피트 바닥에서 위로 0.3 m 이하 ★ 두 조건 모두 적합하여야 하므로 압축된 완충기 위치를 고려하여 칸막이 설치
A38: 칸막이 | B38: 6.5.5 | C38: 45323 | E38: [서로 다른 피트간 칸막이] ① 피트 내 작업자공간이 위험구간*이아닌 경우 칸막이 설치 제외 가능 * 피트바닥에서 카 가장 낮은 부품까지의 수직거리가 2m 이상 ② 칸막이와 벽의 거리가 0.3m 이내인 경우 서로 다른 피트간의 접근을 방지할 수 있는 거리로 판단
A39: 칸막이 | B39: 6.5.5 | C39: 43892 | E39: [여러대 있는 엘리베이터의 칸막이] ① 칸막이의 최저점은 피트바닥에서 2m 이하로 적용 ② 종전 검사기준 적용 시 칸막이의 최저점은 최하층 승강장 바닥 이하로 적용
... A71: 카문의 개방 | B71: 7.15.3 | C71: 45119 | E71: [수직개폐식 카문의 개방] ·카문 잠금장치가 설치된 경우 비상잠금해제 삼각열쇠 이외의 도구가 없어도 승강장문을 열면 카문을 열 수 있어야 함
A72: 카의 유효면적, 정격하중 및 정원 | B72: 8.2 | C72: 42763 | E72: [침대용 엘리베이터 교체공사] ① 리모델링(제어반+권상기 포함)하는 경우 현행 안전기준을 적용 ② 현행 안전기준 적용 시 정격용량이 변경되므로 건축물 구조계산, 카 체대, 가이드레일 및 지지부, 로프안전율, 권상능력 등 승강기 강도에 대한 설계서류 제출
A73: 카의 유효면적, 정격하중 및 정원 | B73: 8.2 | C73: 44855 | E73: [병원용 엘리베이터 카 크기] ① 검사판정: 카 크기 판정하지 않음 ② 안내사항: 병원용 엘리베이터 설계 시 발주처와 충분히 협의하여 해당 건축물에 사용되는 병상의 크기 이상으로 출입문 크기를 확보하는 것이 바람직함을 권고 ③ 참고: 의료시설(침상 미사용시설 제외)의 경우 피난용 엘리베이터는 출입문 폭 1,100mm, 카 폭 1,200mm, 카 깊이 2,300mm 이상
A74: 카 면적 | B74: 8.2.1.2 | C74: 45033 | E74: [카 내 용도 외 구조물 설치(진입방지봉 등)] ① 카 내 구조물 신규 설치 불가, 카 내 구조물 기 설치분 철거 ② 철거되지 않은 경우: 조건부합격 판정
A75: 카 벽의 움푹 들어간 공간 또는 확장된 공간의 정원 및 하중 적용 | B75: 8.2.1.3 | C75: 43892 | E75: ① 카 벽의 움푹 들어간 공간 또는 확장된 공간의 높이가 1m 미만이고, 최대 카 유효면적 계산에 고려된 경우에만 설치 가능 ② 해당 공간은 최대 카 유효면적 계산에 고려 ③ 분리형 문으로 보호되는 경우 사람이 탈 수 없으므로 최소 카 유효면적 계산 시 고려하지 않음
A76: 카 내부 표기 | B76: 8.2.3.2 | C76: 42763 | E76: ① 정원, 하중 등 표시 방법(레이저 등) a. 표시 방법은 규정하지 않으며, 표시 상태가 명확한 경우: 적합 b. 표시 상태가 명확하지 않은 경우: 시정권고
A77: 카 내부 표기 | B77: 8.2.3.2 | C77: 43547 | E77: ② 교체 설치하는 승강기의 정원 산정 정원은 건축법령 등 타 법령과 연관된 사항으로 교체하는 승강기의 최초 건축허가일이 '19.3.23. 전의 경우 정격하중 및 권상능력은 현행 안전기준에 모두 적합하여야 하나, 정원은 종전 검사기준에 따라 인당 65 kg로 계산하여 카 내 표시 가능
A78: 카 벽 유리 사용 | B78: 8.3.2.3 | C78: 43559 | E78: ① 카 벽에 유리가 설치된 경우 유리의 유형 및 두께 확인 ★ 개별안전인증 시 추락방지안전장치 작동 후 유리가 미끄러지지 않음을 추가 확인 ② 유리의 모든 면이 틀에 끼어져 있지 않은 경우 충격시험 공인기관 시험성적서 제출 ★ 안전인증을 받은 승강기의 경우 인증 시 충격시험이 수행되었는지 확인
A79: 에이프런 | B79: 8.5.1 | C79: 43892 | E79: [에이프런과 토가드 폭] ① 각 승강장문의 문턱 아랫부분 수직면의 폭은 카 출입구 폭에다 양쪽 모두 25mm를 더한 값 이상 ② 에이프런의 폭은 마주하는 승강장 유효 출입구의 전체 폭 이상
A80: 비상구출문 | B80: 8.6 | C80: 45224 | E80: [천장 교체 시 적용] ① 수단을 마련하는 경우 기존 비상구출문 폐쇄 가능 a. (MR) 카 상부 비상통화장치 설치 b. (MRL) - 비상통화장치+기계적 고정장치 해제 수단 및 매뉴얼 영구 비치 - 비상통화장치+비상문(1.8m × 0.5m) / 승강장문*(0.5m × 0.7m) *승강로밖으로나올수있도록 승강장문 틈새를 확보하는 경우 해당 위치에서 구동기 등 승강기부품 점검이 가능하여야함
A81: 카 지붕 미끄러짐 방지 수단 | B81: 8.7.1 | C81: 43559 | E81: ① 카 지붕의 표면에서 미끄러지지 않게 하여야 함 a. 카 지붕(부분 단면적) 끝단의 내측 모서리의 50mm 이내 제외 가능 b. 미끄럼방지 테이프를 이용하는 경우, 간격없이 부착하여야 함 ★ 전선은 미끄럼방지 수단 내에 포함되지 않도록 테두리에 둘러 구정 마감 ★ 전선이 가로질러 설치되는 경우 덕트를 포함하여 고정 마감 ② 카 지붕 위 체대에 서 있을 수 있는 경우 미끄럼방지수단 적용
A82: 카 지붕 전면부 발 보호판 | B82: 8.7.2 | C82: 43559 | E82: ① 카 지붕의 바깥쪽 가장자리에서 승강로 벽까지의 수평거리와 관계없이 카 지붕의 모서리(전면부 포함)에는 발보호판이 설치되어야 함 ② 카문 오퍼레이터의 보호커버를 발보호판으로 겸용하여 설치가능하나 끼임이 가능한 구조인 경우 부적합 판정
...

Sheet BS
A1: =input!C3 -> 0 | D1: =input!C4 -> 0
A2: 100 | B2: 0.37 | D2: 1 | E2: 0.28
A3: 180 | B3: 0.58 | D3: 2 | E3: 0.49
A4: 225 | B4: 0.7 | D4: 3 | E4: 0.6
A5: 300 | B5: 0.9 | D5: 4 | E5: 0.79
A6: 375 | B6: 1.1 | D6: 5 | E6: 0.98
A7: 400 | B7: 1.17 | D7: 6 | E7: 1.17
A8: 450 | B8: 1.3 | D8: 7 | E8: 1.31
A9: 525 | B9: 1.45 | D9: 8 | E9: 1.45
A10: 600 | B10: 1.6 | D10: 9 | E10: 1.59
A11: 630 | B11: 1.66 | D11: 10 | E11: 1.73
A12: 675 | B12: 1.75 | D12: 11 | E12: 1.87
A13: 750 | B13: 1.9 | D13: 12 | E13: 2.01
... A21: 1250 | B21: 2.8 | D21: 20 | E21: 3.13
A22: 1275 | B22: 2.9
A23: 1350 | B23: 3.1
A24: 1425 | B24: 3.25
A25: 1500 | B25: 3.4
A26: 1600 | B26: 3.56
A27: 2000 | B27: 4.2
A28: 2500 | B28: 5
